Traceback (most recent call last):
  File "/home/qmaai/.local/lib/python3.6/site-packages/redis/connection.py", line 1191, in get_connection
    if connection.can_read():
  File "/home/qmaai/.local/lib/python3.6/site-packages/redis/connection.py", line 729, in can_read
    return self._parser.can_read(timeout)
  File "/home/qmaai/.local/lib/python3.6/site-packages/redis/connection.py", line 313, in can_read
    return self._buffer and self._buffer.can_read(timeout)
  File "/home/qmaai/.local/lib/python3.6/site-packages/redis/connection.py", line 223, in can_read
    raise_on_timeout=False)
  File "/home/qmaai/.local/lib/python3.6/site-packages/redis/connection.py", line 193, in _read_from_socket
    raise ConnectionError(SERVER_CLOSED_CONNECTION_ERROR)
redis.exceptions.ConnectionError: Connection closed by server.

During handling of the above exception, another exception occurred:

Traceback (most recent call last):
  File "/home/qmaai/.local/lib/python3.6/site-packages/redis/connection.py", line 552, in connect
    sock = self._connect()
  File "/home/qmaai/.local/lib/python3.6/site-packages/redis/connection.py", line 609, in _connect
    raise err
  File "/home/qmaai/.local/lib/python3.6/site-packages/redis/connection.py", line 597, in _connect
    sock.connect(socket_address)
ConnectionRefusedError: [Errno 111] Connection refused

During handling of the above exception, another exception occurred:

Traceback (most recent call last):
  File "/home/qmaai/.local/lib/python3.6/site-packages/ray/log_monitor.py", line 297, in <module>
    log_monitor.run()
  File "/home/qmaai/.local/lib/python3.6/site-packages/ray/log_monitor.py", line 248, in run
    anything_published = self.check_log_files_and_publish_updates()
  File "/home/qmaai/.local/lib/python3.6/site-packages/ray/log_monitor.py", line 233, in check_log_files_and_publish_updates
    "lines": lines_to_publish
  File "/home/qmaai/.local/lib/python3.6/site-packages/redis/client.py", line 3046, in publish
    return self.execute_command('PUBLISH', channel, message)
  File "/home/qmaai/.local/lib/python3.6/site-packages/redis/client.py", line 875, in execute_command
    conn = self.connection or pool.get_connection(command_name, **options)
  File "/home/qmaai/.local/lib/python3.6/site-packages/redis/connection.py", line 1195, in get_connection
    connection.connect()
  File "/home/qmaai/.local/lib/python3.6/site-packages/redis/connection.py", line 557, in connect
    raise ConnectionError(self._error_message(e))
redis.exceptions.ConnectionError: Error 111 connecting to 10.164.8.103:20672. Connection refused.

During handling of the above exception, another exception occurred:

Traceback (most recent call last):
  File "/home/qmaai/.local/lib/python3.6/site-packages/redis/connection.py", line 552, in connect
    sock = self._connect()
  File "/home/qmaai/.local/lib/python3.6/site-packages/redis/connection.py", line 609, in _connect
    raise err
  File "/home/qmaai/.local/lib/python3.6/site-packages/redis/connection.py", line 597, in _connect
    sock.connect(socket_address)
ConnectionRefusedError: [Errno 111] Connection refused

During handling of the above exception, another exception occurred:

Traceback (most recent call last):
  File "/home/qmaai/.local/lib/python3.6/site-packages/ray/log_monitor.py", line 306, in <module>
    redis_client, ray_constants.LOG_MONITOR_DIED_ERROR, message)
  File "/home/qmaai/.local/lib/python3.6/site-packages/ray/utils.py", line 123, in push_error_to_driver_through_redis
    error_data)
  File "/home/qmaai/.local/lib/python3.6/site-packages/redis/client.py", line 875, in execute_command
    conn = self.connection or pool.get_connection(command_name, **options)
  File "/home/qmaai/.local/lib/python3.6/site-packages/redis/connection.py", line 1185, in get_connection
    connection.connect()
  File "/home/qmaai/.local/lib/python3.6/site-packages/redis/connection.py", line 557, in connect
    raise ConnectionError(self._error_message(e))
redis.exceptions.ConnectionError: Error 111 connecting to 10.164.8.103:20672. Connection refused.
